{
  "schema": "hmsc-int.voxel-blockout.v1",
  "exportedAt": "2026-06-07T05:49:19.556Z",
  "dims": {
    "w": 5,
    "d": 6,
    "h": 7
  },
  "blocks": [
    {
      "x": 2,
      "y": 1,
      "z": 3,
      "kind": "wall"
    },
    {
      "x": 2,
      "y": 2,
      "z": 3,
      "kind": "wall"
    },
    {
      "x": 2,
      "y": 1,
      "z": 2,
      "kind": "wall"
    },
    {
      "x": 2,
      "y": 2,
      "z": 2,
      "kind": "wall"
    },
    {
      "x": 3,
      "y": 1,
      "z": 2,
      "kind": "wall"
    },
    {
      "x": 3,
      "y": 1,
      "z": 1,
      "kind": "wall"
    },
    {
      "x": 2,
      "y": 1,
      "z": 1,
      "kind": "wall"
    },
    {
      "x": 1,
      "y": 1,
      "z": 2,
      "kind": "wall"
    },
    {
      "x": 1,
      "y": 1,
      "z": 1,
      "kind": "wall"
    },
    {
      "x": 1,
      "y": 1,
      "z": 3,
      "kind": "wall"
    },
    {
      "x": 2,
      "y": 1,
      "z": 4,
      "kind": "wall"
    },
    {
      "x": 1,
      "y": 1,
      "z": 4,
      "kind": "wall"
    },
    {
      "x": 3,
      "y": 1,
      "z": 3,
      "kind": "wall"
    },
    {
      "x": 3,
      "y": 1,
      "z": 4,
      "kind": "wall"
    },
    {
      "x": 2,
      "y": 3,
      "z": 3,
      "kind": "wall"
    },
    {
      "x": 2,
      "y": 3,
      "z": 2,
      "kind": "wall"
    },
    {
      "x": 2,
      "y": 4,
      "z": 3,
      "kind": "wall"
    },
    {
      "x": 2,
      "y": 4,
      "z": 2,
      "kind": "wall"
    },
    {
      "x": 2,
      "y": 5,
      "z": 3,
      "kind": "wall"
    },
    {
      "x": 2,
      "y": 5,
      "z": 2,
      "kind": "wall"
    },
    {
      "x": 2,
      "y": 6,
      "z": 3,
      "kind": "wall"
    },
    {
      "x": 2,
      "y": 6,
      "z": 2,
      "kind": "wall"
    }
  ],
  "artificialFloor": {
    "y": 0,
    "width": 5,
    "depth": 6
  },
  "faceGroups": [
    {
      "id": "yn_floor_0_2",
      "face": "yn",
      "normal": {
        "x": 0,
        "y": -1,
        "z": 0
      },
      "kind": "floor",
      "plane": 0,
      "bounds": {
        "u0": 0,
        "v0": 0,
        "u1": 5,
        "v1": 6
      },
      "cells": [
        {
          "x": 0,
          "y": 0,
          "z": 0,
          "u": 0,
          "v": 0
        },
        {
          "x": 0,
          "y": 0,
          "z": 1,
          "u": 0,
          "v": 1
        },
        {
          "x": 0,
          "y": 0,
          "z": 2,
          "u": 0,
          "v": 2
        },
        {
          "x": 0,
          "y": 0,
          "z": 3,
          "u": 0,
          "v": 3
        },
        {
          "x": 0,
          "y": 0,
          "z": 4,
          "u": 0,
          "v": 4
        },
        {
          "x": 0,
          "y": 0,
          "z": 5,
          "u": 0,
          "v": 5
        },
        {
          "x": 1,
          "y": 0,
          "z": 5,
          "u": 1,
          "v": 5
        },
        {
          "x": 2,
          "y": 0,
          "z": 5,
          "u": 2,
          "v": 5
        },
        {
          "x": 2,
          "y": 0,
          "z": 4,
          "u": 2,
          "v": 4
        },
        {
          "x": 2,
          "y": 0,
          "z": 3,
          "u": 2,
          "v": 3
        },
        {
          "x": 2,
          "y": 0,
          "z": 2,
          "u": 2,
          "v": 2
        },
        {
          "x": 2,
          "y": 0,
          "z": 1,
          "u": 2,
          "v": 1
        },
        {
          "x": 2,
          "y": 0,
          "z": 0,
          "u": 2,
          "v": 0
        },
        {
          "x": 3,
          "y": 0,
          "z": 0,
          "u": 3,
          "v": 0
        },
        {
          "x": 4,
          "y": 0,
          "z": 0,
          "u": 4,
          "v": 0
        },
        {
          "x": 4,
          "y": 0,
          "z": 1,
          "u": 4,
          "v": 1
        },
        {
          "x": 4,
          "y": 0,
          "z": 2,
          "u": 4,
          "v": 2
        },
        {
          "x": 4,
          "y": 0,
          "z": 3,
          "u": 4,
          "v": 3
        },
        {
          "x": 4,
          "y": 0,
          "z": 4,
          "u": 4,
          "v": 4
        },
        {
          "x": 4,
          "y": 0,
          "z": 5,
          "u": 4,
          "v": 5
        },
        {
          "x": 3,
          "y": 0,
          "z": 1,
          "u": 3,
          "v": 1
        },
        {
          "x": 3,
          "y": 0,
          "z": 2,
          "u": 3,
          "v": 2
        },
        {
          "x": 3,
          "y": 0,
          "z": 3,
          "u": 3,
          "v": 3
        },
        {
          "x": 3,
          "y": 0,
          "z": 4,
          "u": 3,
          "v": 4
        },
        {
          "x": 3,
          "y": 0,
          "z": 5,
          "u": 3,
          "v": 5
        },
        {
          "x": 1,
          "y": 0,
          "z": 4,
          "u": 1,
          "v": 4
        },
        {
          "x": 1,
          "y": 0,
          "z": 3,
          "u": 1,
          "v": 3
        },
        {
          "x": 1,
          "y": 0,
          "z": 2,
          "u": 1,
          "v": 2
        },
        {
          "x": 1,
          "y": 0,
          "z": 1,
          "u": 1,
          "v": 1
        },
        {
          "x": 1,
          "y": 0,
          "z": 0,
          "u": 1,
          "v": 0
        }
      ],
      "textureKey": "floor/yn/yn_floor_0_2"
    },
    {
      "id": "yp_floor_1_1",
      "face": "yp",
      "normal": {
        "x": 0,
        "y": 1,
        "z": 0
      },
      "kind": "floor",
      "plane": 1,
      "bounds": {
        "u0": 0,
        "v0": 0,
        "u1": 5,
        "v1": 6
      },
      "cells": [
        {
          "x": 0,
          "y": 0,
          "z": 0,
          "u": 0,
          "v": 0
        },
        {
          "x": 0,
          "y": 0,
          "z": 1,
          "u": 0,
          "v": 1
        },
        {
          "x": 0,
          "y": 0,
          "z": 2,
          "u": 0,
          "v": 2
        },
        {
          "x": 0,
          "y": 0,
          "z": 3,
          "u": 0,
          "v": 3
        },
        {
          "x": 0,
          "y": 0,
          "z": 4,
          "u": 0,
          "v": 4
        },
        {
          "x": 0,
          "y": 0,
          "z": 5,
          "u": 0,
          "v": 5
        },
        {
          "x": 1,
          "y": 0,
          "z": 5,
          "u": 1,
          "v": 5
        },
        {
          "x": 2,
          "y": 0,
          "z": 5,
          "u": 2,
          "v": 5
        },
        {
          "x": 3,
          "y": 0,
          "z": 5,
          "u": 3,
          "v": 5
        },
        {
          "x": 4,
          "y": 0,
          "z": 5,
          "u": 4,
          "v": 5
        },
        {
          "x": 4,
          "y": 0,
          "z": 4,
          "u": 4,
          "v": 4
        },
        {
          "x": 4,
          "y": 0,
          "z": 3,
          "u": 4,
          "v": 3
        },
        {
          "x": 4,
          "y": 0,
          "z": 2,
          "u": 4,
          "v": 2
        },
        {
          "x": 4,
          "y": 0,
          "z": 1,
          "u": 4,
          "v": 1
        },
        {
          "x": 4,
          "y": 0,
          "z": 0,
          "u": 4,
          "v": 0
        },
        {
          "x": 3,
          "y": 0,
          "z": 0,
          "u": 3,
          "v": 0
        },
        {
          "x": 2,
          "y": 0,
          "z": 0,
          "u": 2,
          "v": 0
        },
        {
          "x": 1,
          "y": 0,
          "z": 0,
          "u": 1,
          "v": 0
        }
      ],
      "textureKey": "floor/yp/yp_floor_1_1"
    },
    {
      "id": "xn_wall_2_7",
      "face": "xn",
      "normal": {
        "x": -1,
        "y": 0,
        "z": 0
      },
      "kind": "wall",
      "plane": 2,
      "bounds": {
        "u0": 2,
        "v0": 2,
        "u1": 4,
        "v1": 7
      },
      "cells": [
        {
          "x": 2,
          "y": 2,
          "z": 3,
          "u": 3,
          "v": 2
        },
        {
          "x": 2,
          "y": 3,
          "z": 3,
          "u": 3,
          "v": 3
        },
        {
          "x": 2,
          "y": 4,
          "z": 3,
          "u": 3,
          "v": 4
        },
        {
          "x": 2,
          "y": 5,
          "z": 3,
          "u": 3,
          "v": 5
        },
        {
          "x": 2,
          "y": 6,
          "z": 3,
          "u": 3,
          "v": 6
        },
        {
          "x": 2,
          "y": 6,
          "z": 2,
          "u": 2,
          "v": 6
        },
        {
          "x": 2,
          "y": 5,
          "z": 2,
          "u": 2,
          "v": 5
        },
        {
          "x": 2,
          "y": 4,
          "z": 2,
          "u": 2,
          "v": 4
        },
        {
          "x": 2,
          "y": 3,
          "z": 2,
          "u": 2,
          "v": 3
        },
        {
          "x": 2,
          "y": 2,
          "z": 2,
          "u": 2,
          "v": 2
        }
      ],
      "textureKey": "wall/xn/xn_wall_2_7"
    },
    {
      "id": "xp_wall_3_6",
      "face": "xp",
      "normal": {
        "x": 1,
        "y": 0,
        "z": 0
      },
      "kind": "wall",
      "plane": 3,
      "bounds": {
        "u0": 2,
        "v0": 2,
        "u1": 4,
        "v1": 7
      },
      "cells": [
        {
          "x": 2,
          "y": 2,
          "z": 3,
          "u": 3,
          "v": 2
        },
        {
          "x": 2,
          "y": 3,
          "z": 3,
          "u": 3,
          "v": 3
        },
        {
          "x": 2,
          "y": 4,
          "z": 3,
          "u": 3,
          "v": 4
        },
        {
          "x": 2,
          "y": 5,
          "z": 3,
          "u": 3,
          "v": 5
        },
        {
          "x": 2,
          "y": 6,
          "z": 3,
          "u": 3,
          "v": 6
        },
        {
          "x": 2,
          "y": 6,
          "z": 2,
          "u": 2,
          "v": 6
        },
        {
          "x": 2,
          "y": 5,
          "z": 2,
          "u": 2,
          "v": 5
        },
        {
          "x": 2,
          "y": 4,
          "z": 2,
          "u": 2,
          "v": 4
        },
        {
          "x": 2,
          "y": 3,
          "z": 2,
          "u": 2,
          "v": 3
        },
        {
          "x": 2,
          "y": 2,
          "z": 2,
          "u": 2,
          "v": 2
        }
      ],
      "textureKey": "wall/xp/xp_wall_3_6"
    },
    {
      "id": "yp_wall_2_11",
      "face": "yp",
      "normal": {
        "x": 0,
        "y": 1,
        "z": 0
      },
      "kind": "wall",
      "plane": 2,
      "bounds": {
        "u0": 1,
        "v0": 1,
        "u1": 4,
        "v1": 5
      },
      "cells": [
        {
          "x": 3,
          "y": 1,
          "z": 2,
          "u": 3,
          "v": 2
        },
        {
          "x": 3,
          "y": 1,
          "z": 1,
          "u": 3,
          "v": 1
        },
        {
          "x": 2,
          "y": 1,
          "z": 1,
          "u": 2,
          "v": 1
        },
        {
          "x": 1,
          "y": 1,
          "z": 1,
          "u": 1,
          "v": 1
        },
        {
          "x": 1,
          "y": 1,
          "z": 2,
          "u": 1,
          "v": 2
        },
        {
          "x": 1,
          "y": 1,
          "z": 3,
          "u": 1,
          "v": 3
        },
        {
          "x": 1,
          "y": 1,
          "z": 4,
          "u": 1,
          "v": 4
        },
        {
          "x": 2,
          "y": 1,
          "z": 4,
          "u": 2,
          "v": 4
        },
        {
          "x": 3,
          "y": 1,
          "z": 4,
          "u": 3,
          "v": 4
        },
        {
          "x": 3,
          "y": 1,
          "z": 3,
          "u": 3,
          "v": 3
        }
      ],
      "textureKey": "wall/yp/yp_wall_2_11"
    },
    {
      "id": "xn_floor_0_0",
      "face": "xn",
      "normal": {
        "x": -1,
        "y": 0,
        "z": 0
      },
      "kind": "floor",
      "plane": 0,
      "bounds": {
        "u0": 0,
        "v0": 0,
        "u1": 6,
        "v1": 1
      },
      "cells": [
        {
          "x": 0,
          "y": 0,
          "z": 0,
          "u": 0,
          "v": 0
        },
        {
          "x": 0,
          "y": 0,
          "z": 1,
          "u": 1,
          "v": 0
        },
        {
          "x": 0,
          "y": 0,
          "z": 2,
          "u": 2,
          "v": 0
        },
        {
          "x": 0,
          "y": 0,
          "z": 3,
          "u": 3,
          "v": 0
        },
        {
          "x": 0,
          "y": 0,
          "z": 4,
          "u": 4,
          "v": 0
        },
        {
          "x": 0,
          "y": 0,
          "z": 5,
          "u": 5,
          "v": 0
        }
      ],
      "textureKey": "floor/xn/xn_floor_0_0"
    },
    {
      "id": "xp_floor_5_4",
      "face": "xp",
      "normal": {
        "x": 1,
        "y": 0,
        "z": 0
      },
      "kind": "floor",
      "plane": 5,
      "bounds": {
        "u0": 0,
        "v0": 0,
        "u1": 6,
        "v1": 1
      },
      "cells": [
        {
          "x": 4,
          "y": 0,
          "z": 0,
          "u": 0,
          "v": 0
        },
        {
          "x": 4,
          "y": 0,
          "z": 1,
          "u": 1,
          "v": 0
        },
        {
          "x": 4,
          "y": 0,
          "z": 2,
          "u": 2,
          "v": 0
        },
        {
          "x": 4,
          "y": 0,
          "z": 3,
          "u": 3,
          "v": 0
        },
        {
          "x": 4,
          "y": 0,
          "z": 4,
          "u": 4,
          "v": 0
        },
        {
          "x": 4,
          "y": 0,
          "z": 5,
          "u": 5,
          "v": 0
        }
      ],
      "textureKey": "floor/xp/xp_floor_5_4"
    },
    {
      "id": "zn_floor_0_3",
      "face": "zn",
      "normal": {
        "x": 0,
        "y": 0,
        "z": -1
      },
      "kind": "floor",
      "plane": 0,
      "bounds": {
        "u0": 0,
        "v0": 0,
        "u1": 5,
        "v1": 1
      },
      "cells": [
        {
          "x": 0,
          "y": 0,
          "z": 0,
          "u": 0,
          "v": 0
        },
        {
          "x": 1,
          "y": 0,
          "z": 0,
          "u": 1,
          "v": 0
        },
        {
          "x": 2,
          "y": 0,
          "z": 0,
          "u": 2,
          "v": 0
        },
        {
          "x": 3,
          "y": 0,
          "z": 0,
          "u": 3,
          "v": 0
        },
        {
          "x": 4,
          "y": 0,
          "z": 0,
          "u": 4,
          "v": 0
        }
      ],
      "textureKey": "floor/zn/zn_floor_0_3"
    },
    {
      "id": "zn_wall_2_9",
      "face": "zn",
      "normal": {
        "x": 0,
        "y": 0,
        "z": -1
      },
      "kind": "wall",
      "plane": 2,
      "bounds": {
        "u0": 2,
        "v0": 2,
        "u1": 3,
        "v1": 7
      },
      "cells": [
        {
          "x": 2,
          "y": 2,
          "z": 2,
          "u": 2,
          "v": 2
        },
        {
          "x": 2,
          "y": 3,
          "z": 2,
          "u": 2,
          "v": 3
        },
        {
          "x": 2,
          "y": 4,
          "z": 2,
          "u": 2,
          "v": 4
        },
        {
          "x": 2,
          "y": 5,
          "z": 2,
          "u": 2,
          "v": 5
        },
        {
          "x": 2,
          "y": 6,
          "z": 2,
          "u": 2,
          "v": 6
        }
      ],
      "textureKey": "wall/zn/zn_wall_2_9"
    },
    {
      "id": "zp_floor_6_5",
      "face": "zp",
      "normal": {
        "x": 0,
        "y": 0,
        "z": 1
      },
      "kind": "floor",
      "plane": 6,
      "bounds": {
        "u0": 0,
        "v0": 0,
        "u1": 5,
        "v1": 1
      },
      "cells": [
        {
          "x": 0,
          "y": 0,
          "z": 5,
          "u": 0,
          "v": 0
        },
        {
          "x": 1,
          "y": 0,
          "z": 5,
          "u": 1,
          "v": 0
        },
        {
          "x": 2,
          "y": 0,
          "z": 5,
          "u": 2,
          "v": 0
        },
        {
          "x": 3,
          "y": 0,
          "z": 5,
          "u": 3,
          "v": 0
        },
        {
          "x": 4,
          "y": 0,
          "z": 5,
          "u": 4,
          "v": 0
        }
      ],
      "textureKey": "floor/zp/zp_floor_6_5"
    },
    {
      "id": "zp_wall_4_8",
      "face": "zp",
      "normal": {
        "x": 0,
        "y": 0,
        "z": 1
      },
      "kind": "wall",
      "plane": 4,
      "bounds": {
        "u0": 2,
        "v0": 2,
        "u1": 3,
        "v1": 7
      },
      "cells": [
        {
          "x": 2,
          "y": 2,
          "z": 3,
          "u": 2,
          "v": 2
        },
        {
          "x": 2,
          "y": 3,
          "z": 3,
          "u": 2,
          "v": 3
        },
        {
          "x": 2,
          "y": 4,
          "z": 3,
          "u": 2,
          "v": 4
        },
        {
          "x": 2,
          "y": 5,
          "z": 3,
          "u": 2,
          "v": 5
        },
        {
          "x": 2,
          "y": 6,
          "z": 3,
          "u": 2,
          "v": 6
        }
      ],
      "textureKey": "wall/zp/zp_wall_4_8"
    },
    {
      "id": "xn_wall_1_13",
      "face": "xn",
      "normal": {
        "x": -1,
        "y": 0,
        "z": 0
      },
      "kind": "wall",
      "plane": 1,
      "bounds": {
        "u0": 1,
        "v0": 1,
        "u1": 5,
        "v1": 2
      },
      "cells": [
        {
          "x": 1,
          "y": 1,
          "z": 2,
          "u": 2,
          "v": 1
        },
        {
          "x": 1,
          "y": 1,
          "z": 1,
          "u": 1,
          "v": 1
        },
        {
          "x": 1,
          "y": 1,
          "z": 3,
          "u": 3,
          "v": 1
        },
        {
          "x": 1,
          "y": 1,
          "z": 4,
          "u": 4,
          "v": 1
        }
      ],
      "textureKey": "wall/xn/xn_wall_1_13"
    },
    {
      "id": "xp_wall_4_10",
      "face": "xp",
      "normal": {
        "x": 1,
        "y": 0,
        "z": 0
      },
      "kind": "wall",
      "plane": 4,
      "bounds": {
        "u0": 1,
        "v0": 1,
        "u1": 5,
        "v1": 2
      },
      "cells": [
        {
          "x": 3,
          "y": 1,
          "z": 2,
          "u": 2,
          "v": 1
        },
        {
          "x": 3,
          "y": 1,
          "z": 1,
          "u": 1,
          "v": 1
        },
        {
          "x": 3,
          "y": 1,
          "z": 3,
          "u": 3,
          "v": 1
        },
        {
          "x": 3,
          "y": 1,
          "z": 4,
          "u": 4,
          "v": 1
        }
      ],
      "textureKey": "wall/xp/xp_wall_4_10"
    },
    {
      "id": "zn_wall_1_12",
      "face": "zn",
      "normal": {
        "x": 0,
        "y": 0,
        "z": -1
      },
      "kind": "wall",
      "plane": 1,
      "bounds": {
        "u0": 1,
        "v0": 1,
        "u1": 4,
        "v1": 2
      },
      "cells": [
        {
          "x": 3,
          "y": 1,
          "z": 1,
          "u": 3,
          "v": 1
        },
        {
          "x": 2,
          "y": 1,
          "z": 1,
          "u": 2,
          "v": 1
        },
        {
          "x": 1,
          "y": 1,
          "z": 1,
          "u": 1,
          "v": 1
        }
      ],
      "textureKey": "wall/zn/zn_wall_1_12"
    },
    {
      "id": "zp_wall_5_14",
      "face": "zp",
      "normal": {
        "x": 0,
        "y": 0,
        "z": 1
      },
      "kind": "wall",
      "plane": 5,
      "bounds": {
        "u0": 1,
        "v0": 1,
        "u1": 4,
        "v1": 2
      },
      "cells": [
        {
          "x": 2,
          "y": 1,
          "z": 4,
          "u": 2,
          "v": 1
        },
        {
          "x": 1,
          "y": 1,
          "z": 4,
          "u": 1,
          "v": 1
        },
        {
          "x": 3,
          "y": 1,
          "z": 4,
          "u": 3,
          "v": 1
        }
      ],
      "textureKey": "wall/zp/zp_wall_5_14"
    },
    {
      "id": "yp_wall_7_15",
      "face": "yp",
      "normal": {
        "x": 0,
        "y": 1,
        "z": 0
      },
      "kind": "wall",
      "plane": 7,
      "bounds": {
        "u0": 2,
        "v0": 2,
        "u1": 3,
        "v1": 4
      },
      "cells": [
        {
          "x": 2,
          "y": 6,
          "z": 3,
          "u": 2,
          "v": 3
        },
        {
          "x": 2,
          "y": 6,
          "z": 2,
          "u": 2,
          "v": 2
        }
      ],
      "textureKey": "wall/yp/yp_wall_7_15"
    }
  ]
}